<?xml version="1.0"?>
<robot xmlns:xacro="http://ros.org/wiki/xacro">

  <!-- Import Rviz colors -->
  <xacro:include filename="$(find protac_description)/urdf/protac.material.xacro" />

  <xacro:macro name="protac" params="parent *origin">
    <link name="base_link">
      <inertial>
        <origin rpy="0 0 0" xyz="-4.0682e-11 5.8587e-06 0.05729"/>
        <mass value="0.005"/>
        <inertia ixx="9.4e-05" ixy="-0.0" ixz="0.0" iyy="5.5e-05" iyz="0.0" izz="8.2e-05"/>
      </inertial>
      <visual>
        <origin rpy="0 0 0" xyz="0 0 0"/>
        <geometry>
          <mesh filename="package://protac_description/meshes/base_link.STL"/>
        </geometry>
        <material name="grey"/>
      </visual>
      <collision>
        <origin rpy="0 0 0" xyz="0 0 0"/>
        <geometry>
          <mesh filename="package://protac_description/meshes/base_link.STL"/>
        </geometry>
      </collision>
    </link>

    <link name="link_1">
      <inertial>
        <origin rpy="0 0 0" xyz="-4.2889e-11 0.0036799 0.032082"/>
        <mass value="0.005"/>
        <inertia ixx="3e-06" ixy="-0.0" ixz="-0.0" iyy="1e-06" iyz="0.0" izz="4e-06"/>
      </inertial>
      <visual>
        <origin rpy="0 0 0" xyz="0 0 0"/>
        <geometry>
          <mesh filename="package://protac_description/meshes/link1.STL"/>
        </geometry>
        <material name="grey"/>
      </visual>
      <collision>
        <origin rpy="0 0 0" xyz="0 0 0"/>
        <geometry>
          <mesh filename="package://protac_description/meshes/link1.STL"/>
        </geometry>
      </collision>
    </link>

    <link name="link_2">
      <inertial>
        <origin rpy="0 0 0" xyz="4.0646e-05 -0.28131 -0.0044042"/>
        <mass value="0.005"/>
        <inertia ixx="9.4e-05" ixy="0.0" ixz="-0.0" iyy="8.2e-05" iyz="0.0" izz="5.5e-05"/>
      </inertial>
      <visual>
        <origin rpy="0 0 0" xyz="0 0 0"/>
        <geometry>
          <mesh filename="package://protac_description/meshes/link2.STL"/>
        </geometry>
        <material name="grey"/>
      </visual>
      <collision>
        <origin rpy="0 0 0" xyz="0 0 0"/>
        <geometry>
          <mesh filename="package://protac_description/meshes/link2.STL"/>
        </geometry>
      </collision>
    </link>

    <link name="link_3">
      <inertial>
        <origin rpy="0 0 0" xyz="0.01294 3.5796e-05 0.025586"/>
        <mass value="0.005"/>
        <inertia ixx="3.2e-05" ixy="-0.0" ixz="0.0" iyy="2e-05" iyz="-0.0" izz="1.9e-05"/>
      </inertial>
      <visual>
        <origin rpy="0 0 0" xyz="0 0 0"/>
        <geometry>
          <mesh filename="package://protac_description/meshes/link3.STL"/>
        </geometry>
        <material name="grey"/>
      </visual>
      <collision>
        <origin rpy="0 0 0" xyz="0 0 0"/>
        <geometry>
          <mesh filename="package://protac_description/meshes/link3.STL"/>
        </geometry>
      </collision>
    </link>

    <link name="link_4">
      <inertial>
        <origin rpy="0 0 0" xyz="0.0052747 0.00023019 0.17217"/>
        <mass value="0.005"/>
        <inertia ixx="3.2e-05" ixy="-0.0" ixz="0.0" iyy="2e-05" iyz="-0.0" izz="1.9e-05"/>
      </inertial>
      <visual>
        <origin rpy="0 0 0" xyz="0 0 0"/>
        <geometry>
          <mesh filename="package://protac_description/meshes/link4.STL"/>
        </geometry>
        <material name="grey"/>
      </visual>
      <collision>
        <origin rpy="0 0 0" xyz="0 0 0"/>
        <geometry>
          <mesh filename="package://protac_description/meshes/link4.STL"/>
        </geometry>
      </collision>
    </link>

    <link name="eef_link">
      <inertial>
        <origin rpy="0 0 0" xyz="0.00105476762353651 -0.00054399845541328 -0.00395532957526007"/>
        <mass value="0.001"/>
        <inertia ixx="3.2e-05" ixy="-0.0" ixz="0.0" iyy="2e-05" iyz="-0.0" izz="1.9e-05"/>
      </inertial>
      <visual>
        <origin rpy="0 0 0" xyz="0 0 0"/>
        <geometry>
          <mesh filename="package://protac_description/meshes/eef_link.STL"/>
        </geometry>
        <material name="grey"/>
      </visual>
      <collision>
        <origin rpy="0 0 0" xyz="0 0 0"/>
        <geometry>
          <mesh filename="package://protac_description/meshes/eef_link.STL"/>
        </geometry>
      </collision>
    </link>

    <joint name="origin_to_base_link" type="fixed">
      <xacro:insert_block name="origin" />
      <parent link="${parent}" />
      <child link="base_link" />
    </joint>

    <joint name="joint1" type="revolute">
      <origin rpy="${-radians(90)} 0 0" xyz="0. 0. 0.159"/>
      <parent link="base_link"/>
      <child link="link_1"/>
      <axis xyz="0.0 -1.0 0.0"/>
      <limit effort="10" lower="${-radians(160)}" upper="${radians(160)}" velocity="${28 / 60.0 * 2.0 * pi}"/>
      <dynamics damping="0.7" friction="0.7"/>
    </joint>

    <joint name="joint2" type="revolute">
      <origin rpy="0 0 0" xyz="0. 0. 0.092"/>
      <parent link="link_1"/>
      <child link="link_2"/>
      <axis xyz="0.0 0.0 1.0"/>
      <limit effort="44" lower="${-radians(160)}" upper="${radians(160)}" velocity="${28 / 60.0 * 2.0 * pi}"/>
      <dynamics damping="0.7" friction="0.7"/>
    </joint>

    <joint name="joint3" type="revolute">
      <origin rpy="${radians(90)} 0. 0." xyz="0. -0.4 -0.102"/>
      <parent link="link_2"/>
      <child link="link_3"/>
      <axis xyz="0.0 -1.0 0.0"/>
      <limit effort="25" lower="${-radians(160)}" upper="${radians(160)}" velocity="${28 / 60.0 * 2.0 * pi}"/>
      <dynamics damping="0.7" friction="0.7"/>
    </joint>

    <joint name="joint4" type="revolute">
      <origin rpy="0 0 0" xyz="0. 0. 0.051"/>
      <parent link="link_3"/>
      <child link="link_4"/>
      <axis xyz="0.0 0.0 1.0"/>
      <limit effort="5" lower="${-radians(160)}" upper="${radians(160)}" velocity="${28 / 60.0 * 2.0 * pi}"/>
      <dynamics damping="0.7" friction="0.7"/>
    </joint>

    <joint name="joint5" type="fixed">
      <origin rpy="0 0 0" xyz="0. 0. 0.31"/>
      <parent link="link_4"/>
      <child link="eef_link"/>
    </joint>

  </xacro:macro>
</robot>
