<?xml version="1.0" ?>
<!-- =================================================================================== -->
<!-- |    This document was autogenerated by xacro from protac_gazebo.urdf.xacro       | -->
<!-- |    EDITING THIS FILE BY HAND IS NOT RECOMMENDED                                 | -->
<!-- =================================================================================== -->
<robot name="protac">
  <material name="black">
    <color rgba="0.0 0.0 0.0 1.0"/>
  </material>
  <material name="white">
    <color rgba="1.0 1.0 1.0 1.0"/>
  </material>
  <material name="red">
    <color rgba="0.8 0.0 0.0 1.0"/>
  </material>
  <material name="blue">
    <color rgba="0.0 0.0 0.8 1.0"/>
  </material>
  <material name="green">
    <color rgba="0.0 0.8 0.0 1.0"/>
  </material>
  <material name="grey">
    <color rgba="0.5 0.5 0.5 1.0"/>
  </material>
  <link name="world"/>
  <link name="base_link">
    <inertial>
      <origin rpy="0 0 0" xyz="-4.0682e-11 5.8587e-06 0.05729"/>
      <mass value="0.36412"/>
      <inertia ixx="9.4e-05" ixy="-0.0" ixz="0.0" iyy="5.5e-05" iyz="0.0" izz="8.2e-05"/>
    </inertial>
    <visual>
      <origin rpy="0 0 0" xyz="0 0 0"/>
      <geometry>
        <mesh filename="package://protac_description/meshes/base_link.STL"/>
      </geometry>
      <material name="grey"/>
    </visual>
    <collision>
      <origin rpy="0 0 0" xyz="0 0 0"/>
      <geometry>
        <mesh filename="package://protac_description/meshes/base_link.STL"/>
      </geometry>
    </collision>
  </link>
  <link name="link_1">
    <inertial>
      <origin rpy="0 0 0" xyz="-4.2889e-11 0.0036799 0.032082"/>
      <mass value="0.34495"/>
      <inertia ixx="3e-06" ixy="-0.0" ixz="-0.0" iyy="1e-06" iyz="0.0" izz="4e-06"/>
    </inertial>
    <visual>
      <origin rpy="0 0 0" xyz="0 0 0"/>
      <geometry>
        <mesh filename="package://protac_description/meshes/link1.STL"/>
      </geometry>
      <material name="grey"/>
    </visual>
    <collision>
      <origin rpy="0 0 0" xyz="0 0 0"/>
      <geometry>
        <mesh filename="package://protac_description/meshes/link1.STL"/>
      </geometry>
    </collision>
  </link>
  <link name="link_2">
    <inertial>
      <origin rpy="0 0 0" xyz="4.0646e-05 -0.28131 -0.0044042"/>
      <mass value="0.80672"/>
      <inertia ixx="9.4e-05" ixy="0.0" ixz="-0.0" iyy="8.2e-05" iyz="0.0" izz="5.5e-05"/>
    </inertial>
    <visual>
      <origin rpy="0 0 0" xyz="0 0 0"/>
      <geometry>
        <mesh filename="package://protac_description/meshes/link2.STL"/>
      </geometry>
      <material name="grey"/>
    </visual>
    <collision>
      <origin rpy="0 0 0" xyz="0 0 0"/>
      <geometry>
        <mesh filename="package://protac_description/meshes/link2.STL"/>
      </geometry>
    </collision>
  </link>
  <link name="link_3">
    <inertial>
      <origin rpy="0 0 0" xyz="0.01294 3.5796e-05 0.025586"/>
      <mass value="0.11389"/>
      <inertia ixx="3.2e-05" ixy="-0.0" ixz="0.0" iyy="2e-05" iyz="-0.0" izz="1.9e-05"/>
    </inertial>
    <visual>
      <origin rpy="0 0 0" xyz="0 0 0"/>
      <geometry>
        <mesh filename="package://protac_description/meshes/link3.STL"/>
      </geometry>
      <material name="grey"/>
    </visual>
    <collision>
      <origin rpy="0 0 0" xyz="0 0 0"/>
      <geometry>
        <mesh filename="package://protac_description/meshes/link3.STL"/>
      </geometry>
    </collision>
  </link>
  <link name="link_4">
    <inertial>
      <origin rpy="0 0 0" xyz="0.0052747 0.00023019 0.17217"/>
      <mass value="0.45303"/>
      <inertia ixx="3.2e-05" ixy="-0.0" ixz="0.0" iyy="2e-05" iyz="-0.0" izz="1.9e-05"/>
    </inertial>
    <visual>
      <origin rpy="0 0 0" xyz="0 0 0"/>
      <geometry>
        <mesh filename="package://protac_description/meshes/link4.STL"/>
      </geometry>
      <material name="grey"/>
    </visual>
    <collision>
      <origin rpy="0 0 0" xyz="0 0 0"/>
      <geometry>
        <mesh filename="package://protac_description/meshes/link4.STL"/>
      </geometry>
    </collision>
  </link>
  <joint name="origin_to_base_link" type="fixed">
    <origin rpy="0 0 0" xyz="0 0 0"/>
    <parent link="world"/>
    <child link="base_link"/>
  </joint>
  <joint name="joint1" type="revolute">
    <origin rpy="0 0 0" xyz="0.0 0.0 0.126"/>
    <parent link="base_link"/>
    <child link="link_1"/>
    <axis xyz="0.0 0.0 1.0"/>
    <limit effort="10" lower="-2.0943951023931953" upper="2.0943951023931953" velocity="2.9321531433504737"/>
    <dynamics damping="0.0" friction="0.0"/>
  </joint>
  <joint name="joint2" type="revolute">
    <origin rpy="-1.5708 0 0" xyz="0.0 0.06897 0.03297"/>
    <parent link="link_1"/>
    <child link="link_2"/>
    <axis xyz="0.0 0.0 1.0"/>
    <limit effort="44" lower="-1.0471975511965976" upper="1.0471975511965976" velocity="2.9321531433504737"/>
    <dynamics damping="0.0" friction="0.0"/>
  </joint>
  <joint name="joint3" type="revolute">
    <origin rpy="3.1416 0 0" xyz="-0.0 -0.39899 -0.07"/>
    <parent link="link_2"/>
    <child link="link_3"/>
    <axis xyz="0.0 0.0 1.0"/>
    <limit effort="25" lower="-2.0943951023931953" upper="2.0943951023931953" velocity="2.9321531433504737"/>
    <dynamics damping="0.0" friction="0.0"/>
  </joint>
  <joint name="joint4" type="revolute">
    <origin rpy="-1.5708 0 -1.5708" xyz="0.051 0.0 0.026963"/>
    <parent link="link_3"/>
    <child link="link_4"/>
    <axis xyz="0.0 0.0 1.0"/>
    <limit effort="5" lower="-2.0943951023931953" upper="2.0943951023931953" velocity="2.9321531433504737"/>
    <dynamics damping="0.0" friction="0.0"/>
  </joint>
  <ros2_control name="protac_ros2_control" type="system">
    <hardware>
      <plugin>gazebo_ros2_control/GazeboSystem</plugin>
    </hardware>
    <joint name="joint1">
      <command_interface name="position">
        <param name="min">-2.0943951023931953</param>
        <param name="max">2.0943951023931953</param>
      </command_interface>
      <command_interface name="velocity">
        <param name="min">-2.9321531433504737</param>
        <param name="max">2.9321531433504737</param>
      </command_interface>
      <state_interface name="position">
        <param name="initial_value">0.0</param>
      </state_interface>
      <state_interface name="velocity"/>
      <state_interface name="effort"/>
    </joint>
    <joint name="joint2">
      <command_interface name="position">
        <param name="min">-1.0471975511965976</param>
        <param name="max">1.0471975511965976</param>
      </command_interface>
      <command_interface name="velocity">
        <param name="min">-2.9321531433504737</param>
        <param name="max">2.9321531433504737</param>
      </command_interface>
      <state_interface name="position">
        <param name="initial_value">0.0</param>
      </state_interface>
      <state_interface name="velocity"/>
      <state_interface name="effort"/>
    </joint>
    <joint name="joint3">
      <command_interface name="position">
        <param name="min">-2.0943951023931953</param>
        <param name="max">2.0943951023931953</param>
      </command_interface>
      <command_interface name="velocity">
        <param name="min">-2.9321531433504737</param>
        <param name="max">2.9321531433504737</param>
      </command_interface>
      <state_interface name="position">
        <param name="initial_value">0.0</param>
      </state_interface>
      <state_interface name="velocity"/>
      <state_interface name="effort"/>
    </joint>
    <joint name="joint4">
      <command_interface name="position">
        <param name="min">-2.0943951023931953</param>
        <param name="max">2.0943951023931953</param>
      </command_interface>
      <command_interface name="velocity">
        <param name="min">-2.9321531433504737</param>
        <param name="max">2.9321531433504737</param>
      </command_interface>
      <state_interface name="position">
        <param name="initial_value">0.0</param>
      </state_interface>
      <state_interface name="velocity"/>
      <state_interface name="effort"/>
    </joint>
  </ros2_control>
  <gazebo>
    <plugin filename="libgazebo_ros2_control.so" name="gazebo_ros2_control">
      <parameters>/home/protac/ros/protac_ws/install/protac_description/share/protac_description/controllers/controllers.yaml</parameters>
    </plugin>
  </gazebo>
</robot>
